Last login: Fri Feb 16 12:14:14 on ttys000
Laurens-Air:~ Laurenglading$ cd Desktop/
Laurens-Air:Desktop Laurenglading$ ls
00c0c_dTVzhggYdK3_600x450.jpg
10993396_2349057321014_8075287845160175938_n.jpg
10998040_2349057481018_3108236464919210892_n.jpg
2v2y71g.jpg.png
6130_large.jpg
Arts Toolkit Final
Correct ImageJ
DSC01099.JPG
Exhibition Proposal Images
IMG_4936.jpg
IMG_5062.jpg
IMG_7040.JPG
IMG_7041.JPG
IMG_7042.JPG
IqWRKYIr.png
OnlyFriendLS_2_1024x1024.jpg
PYTHON
SCHOOL
Screen Shot 2017-07-24 at 10.07.21 PM.png
Screen Shot 2017-10-30 at 11.31.03 PM.png
Screen Shot 2017-12-06 at 5.18.30 PM.png
Screen Shot 2017-12-10 at 1.46.18 PM.png
Screen Shot 2017-12-10 at 3.07.22 PM.png
Screen Shot 2017-12-10 at 3.19.08 PM.png
Screen Shot 2017-12-16 at 11.45.10 PM.png
Screen Shot 2017-12-18 at 3.14.33 AM.png
Screen Shot 2017-12-18 at 3.45.28 AM.png
Screen Shot 2017-12-18 at 4.25.35 AM.png
Screen Shot 2017-12-22 at 12.22.49 AM.png
Screen Shot 2017-12-22 at 12.24.44 AM.png
Screen Shot 2017-12-22 at 12.27.03 AM.png
Screen Shot 2017-12-22 at 12.51.06 AM.png
Screen Shot 2018-01-07 at 12.45.14 PM.png
Screen Shot 2018-02-06 at 6.05.14 PM.png
Screen Shot 2018-02-14 at 5.03.28 PM.png
Screen Shot 2018-02-14 at 5.04.06 PM.png
Screen Shot 2018-02-14 at 5.04.17 PM.png
Screen Shot 2018-02-14 at 5.04.56 PM.png
Screen Shot 2018-02-14 at 5.05.20 PM.png
Screen Shot 2018-02-15 at 10.00.06 PM.png
Unknown-1.jpeg
Unknown.jpeg
WirelessDiagnostics_DX1RC06KGKJT_2018-02-11_12.54.39.tar.gz
WirelessDiagnostics_DX1RC06KGKJT_2018-02-11_13.58.14.tar.gz
animation master
carly
clear_acrylic_fillable_teardrop_ornament_1.jpg
gallery images
poetry project
s-l1600-8.jpg
s-l1600-9.jpg
s-l500.jpg
still image project 1
tumblr_ot0j0fWoqz1v0pcdjo5_1280.jpg
unnamed.jpg
Laurens-Air:Desktop Laurenglading$ cd PYTHON/
.DS_Store           Untitled.ipynb      gutenbergplot.py
.ipynb_checkpoints/ data/               project c/
Laurens-Air:Desktop Laurenglading$ cd PYTHON/
.DS_Store           Untitled.ipynb      gutenbergplot.py
.ipynb_checkpoints/ data/               project c/
Laurens-Air:Desktop Laurenglading$ cd PYTHON/
Laurens-Air:PYTHON Laurenglading$ pip install pipenv
Collecting pipenv
  Downloading pipenv-9.0.3.tar.gz (3.9MB)
    100% |████████████████████████████████| 3.9MB 317kB/s 
Collecting virtualenv (from pipenv)
  Downloading virtualenv-15.1.0-py2.py3-none-any.whl (1.8MB)
    100% |████████████████████████████████| 1.8MB 560kB/s 
Collecting pew>=0.1.26 (from pipenv)
  Downloading pew-1.1.2-py2.py3-none-any.whl
Requirement already satisfied: pip>=9.0.1 in /anaconda3/lib/python3.6/site-packages (from pipenv)
Requirement already satisfied: requests>2.18.0 in /anaconda3/lib/python3.6/site-packages (from pipenv)
Collecting flake8>=3.0.0 (from pipenv)
  Downloading flake8-3.5.0-py2.py3-none-any.whl (69kB)
    100% |████████████████████████████████| 71kB 7.0MB/s 
Requirement already satisfied: urllib3>=1.21.1 in /anaconda3/lib/python3.6/site-packages (from pipenv)
Collecting virtualenv-clone>=0.2.5 (from pew>=0.1.26->pipenv)
  Downloading virtualenv-clone-0.2.6.tar.gz
Requirement already satisfied: setuptools>=17.1 in /anaconda3/lib/python3.6/site-packages (from pew>=0.1.26->pipenv)
Requirement already satisfied: chardet<3.1.0,>=3.0.2 in /anaconda3/lib/python3.6/site-packages (from requests>2.18.0->pipenv)
Requirement already satisfied: idna<2.7,>=2.5 in /anaconda3/lib/python3.6/site-packages (from requests>2.18.0->pipenv)
Requirement already satisfied: certifi>=2017.4.17 in /anaconda3/lib/python3.6/site-packages (from requests>2.18.0->pipenv)
Requirement already satisfied: pyflakes<1.7.0,>=1.5.0 in /anaconda3/lib/python3.6/site-packages (from flake8>=3.0.0->pipenv)
Requirement already satisfied: pycodestyle<2.4.0,>=2.0.0 in /anaconda3/lib/python3.6/site-packages (from flake8>=3.0.0->pipenv)
Requirement already satisfied: mccabe<0.7.0,>=0.6.0 in /anaconda3/lib/python3.6/site-packages (from flake8>=3.0.0->pipenv)
Building wheels for collected packages: pipenv, virtualenv-clone
  Running setup.py bdist_wheel for pipenv ... done
  Stored in directory: /Users/Laurenglading/Library/Caches/pip/wheels/78/cf/b7/549d89ddbafb1cf3da825b97b730a7e1ac75602de9865d036e
  Running setup.py bdist_wheel for virtualenv-clone ... done
  Stored in directory: /Users/Laurenglading/Library/Caches/pip/wheels/24/51/ef/93120d304d240b4b6c2066454250a1626e04f73d34417b956d
Successfully built pipenv virtualenv-clone
Installing collected packages: virtualenv, virtualenv-clone, pew, flake8, pipenv
Successfully installed flake8-3.5.0 pew-1.1.2 pipenv-9.0.3 virtualenv-15.1.0 virtualenv-clone-0.2.6
Laurens-Air:PYTHON Laurenglading$ mkdir django
Laurens-Air:PYTHON Laurenglading$ cd django
Laurens-Air:django Laurenglading$ pipenv install django

Creating a virtualenv for this project…
⠋Using base prefix '/anaconda3'
New python executable in /Users/Laurenglading/.local/share/virtualenvs/django-Gmn16L8d/bin/python
Installing setuptools, pip, wheel...done.

Virtualenv location: /Users/Laurenglading/.local/share/virtualenvs/django-Gmn16L8d
Creating a Pipfile for this project…
Installing django…
Collecting django
  Downloading Django-2.0.2-py3-none-any.whl (7.1MB)
Collecting pytz (from django)
  Downloading pytz-2018.3-py2.py3-none-any.whl (509kB)
Installing collected packages: pytz, django
Successfully installed django-2.0.2 pytz-2018.3

Adding django to Pipfile's [packages]…
Locking [dev-packages] dependencies…
Locking [packages] dependencies…
Updated Pipfile.lock (e101fb)!
Laurens-Air:django Laurenglading$ 
Laurens-Air:django Laurenglading$ pipenv shell
Spawning environment shell (/bin/bash). Use 'exit' to leave.
bash-3.2$ source /Users/Laurenglading/.local/share/virtualenvs/django-Gmn16L8d/bin/activate
(django-Gmn16L8d) bash-3.2$ django-admin startproject mysite .
(django-Gmn16L8d) bash-3.2$ ls
Pipfile		Pipfile.lock	manage.py	mysite
(django-Gmn16L8d) bash-3.2$ python manage.py runserver
Performing system checks...

System check identified no issues (0 silenced).

You have 14 unapplied migration(s). Your project may not work properly until you apply the migrations for app(s): admin, auth, contenttypes, sessions.
Run 'python manage.py migrate' to apply them.

February 16, 2018 - 19:17:14
Django version 2.0.2, using settings 'mysite.settings'
Starting development server at http://127.0.0.1:8000/
Quit the server with CONTROL-C.
[16/Feb/2018 19:18:00] "GET / HTTP/1.1" 200 16348
[16/Feb/2018 19:18:00] "GET /static/admin/css/fonts.css HTTP/1.1" 200 423
[16/Feb/2018 19:18:00] "GET /static/admin/fonts/Roboto-Regular-webfont.woff HTTP/1.1" 200 80304
[16/Feb/2018 19:18:00] "GET /static/admin/fonts/Roboto-Bold-webfont.woff HTTP/1.1" 200 82564
[16/Feb/2018 19:18:00] "GET /static/admin/fonts/Roboto-Light-webfont.woff HTTP/1.1" 200 81348
Not Found: /favicon.ico
[16/Feb/2018 19:18:00] "GET /favicon.ico HTTP/1.1" 404 1972
^C(django-Gmn16L8d) bash-3.2$ 
(django-Gmn16L8d) bash-3.2$ python manage.py startapp pages
(django-Gmn16L8d) bash-3.2$ python manage.py runserver
Performing system checks...

Unhandled exception in thread started by <function check_errors.<locals>.wrapper at 0x106633730>
Traceback (most recent call last):
  File "/Users/Laurenglading/.local/share/virtualenvs/django-Gmn16L8d/lib/python3.6/site-packages/django/urls/resolvers.py", line 538, in url_patterns
    iter(patterns)
TypeError: 'module' object is not iterable

During handling of the above exception, another exception occurred:

Traceback (most recent call last):
  File "/Users/Laurenglading/.local/share/virtualenvs/django-Gmn16L8d/lib/python3.6/site-packages/django/utils/autoreload.py", line 225, in wrapper
    fn(*args, **kwargs)
  File "/Users/Laurenglading/.local/share/virtualenvs/django-Gmn16L8d/lib/python3.6/site-packages/django/core/management/commands/runserver.py", line 121, in inner_run
    self.check(display_num_errors=True)
  File "/Users/Laurenglading/.local/share/virtualenvs/django-Gmn16L8d/lib/python3.6/site-packages/django/core/management/base.py", line 364, in check
    include_deployment_checks=include_deployment_checks,
  File "/Users/Laurenglading/.local/share/virtualenvs/django-Gmn16L8d/lib/python3.6/site-packages/django/core/management/base.py", line 351, in _run_checks
    return checks.run_checks(**kwargs)
  File "/Users/Laurenglading/.local/share/virtualenvs/django-Gmn16L8d/lib/python3.6/site-packages/django/core/checks/registry.py", line 73, in run_checks
    new_errors = check(app_configs=app_configs)
  File "/Users/Laurenglading/.local/share/virtualenvs/django-Gmn16L8d/lib/python3.6/site-packages/django/core/checks/urls.py", line 13, in check_url_config
    return check_resolver(resolver)
  File "/Users/Laurenglading/.local/share/virtualenvs/django-Gmn16L8d/lib/python3.6/site-packages/django/core/checks/urls.py", line 23, in check_resolver
    return check_method()
  File "/Users/Laurenglading/.local/share/virtualenvs/django-Gmn16L8d/lib/python3.6/site-packages/django/urls/resolvers.py", line 398, in check
    warnings.extend(check_resolver(pattern))
  File "/Users/Laurenglading/.local/share/virtualenvs/django-Gmn16L8d/lib/python3.6/site-packages/django/core/checks/urls.py", line 23, in check_resolver
    return check_method()
  File "/Users/Laurenglading/.local/share/virtualenvs/django-Gmn16L8d/lib/python3.6/site-packages/django/urls/resolvers.py", line 397, in check
    for pattern in self.url_patterns:
  File "/Users/Laurenglading/.local/share/virtualenvs/django-Gmn16L8d/lib/python3.6/site-packages/django/utils/functional.py", line 36, in __get__
    res = instance.__dict__[self.name] = self.func(instance)
  File "/Users/Laurenglading/.local/share/virtualenvs/django-Gmn16L8d/lib/python3.6/site-packages/django/urls/resolvers.py", line 545, in url_patterns
    raise ImproperlyConfigured(msg.format(name=self.urlconf_name))
django.core.exceptions.ImproperlyConfigured: The included URLconf '<module 'pages.urls' from '/Users/Laurenglading/Desktop/PYTHON/django/pages/urls.py'>' does not appear to have any patterns in it. If you see valid patterns in the file then the issue is probably caused by a circular import.
ls   	

^C(django-Gmn16L8d) bash-3.2$ python manage.py runserver
Performing system checks...

Unhandled exception in thread started by <function check_errors.<locals>.wrapper at 0x10fdcf730>
Traceback (most recent call last):
  File "/Users/Laurenglading/.local/share/virtualenvs/django-Gmn16L8d/lib/python3.6/site-packages/django/utils/autoreload.py", line 225, in wrapper
    fn(*args, **kwargs)
  File "/Users/Laurenglading/.local/share/virtualenvs/django-Gmn16L8d/lib/python3.6/site-packages/django/core/management/commands/runserver.py", line 121, in inner_run
    self.check(display_num_errors=True)
  File "/Users/Laurenglading/.local/share/virtualenvs/django-Gmn16L8d/lib/python3.6/site-packages/django/core/management/base.py", line 364, in check
    include_deployment_checks=include_deployment_checks,
  File "/Users/Laurenglading/.local/share/virtualenvs/django-Gmn16L8d/lib/python3.6/site-packages/django/core/management/base.py", line 351, in _run_checks
    return checks.run_checks(**kwargs)
  File "/Users/Laurenglading/.local/share/virtualenvs/django-Gmn16L8d/lib/python3.6/site-packages/django/core/checks/registry.py", line 73, in run_checks
    new_errors = check(app_configs=app_configs)
  File "/Users/Laurenglading/.local/share/virtualenvs/django-Gmn16L8d/lib/python3.6/site-packages/django/core/checks/urls.py", line 13, in check_url_config
    return check_resolver(resolver)
  File "/Users/Laurenglading/.local/share/virtualenvs/django-Gmn16L8d/lib/python3.6/site-packages/django/core/checks/urls.py", line 23, in check_resolver
    return check_method()
  File "/Users/Laurenglading/.local/share/virtualenvs/django-Gmn16L8d/lib/python3.6/site-packages/django/urls/resolvers.py", line 397, in check
    for pattern in self.url_patterns:
  File "/Users/Laurenglading/.local/share/virtualenvs/django-Gmn16L8d/lib/python3.6/site-packages/django/utils/functional.py", line 36, in __get__
    res = instance.__dict__[self.name] = self.func(instance)
  File "/Users/Laurenglading/.local/share/virtualenvs/django-Gmn16L8d/lib/python3.6/site-packages/django/urls/resolvers.py", line 536, in url_patterns
    patterns = getattr(self.urlconf_module, "urlpatterns", self.urlconf_module)
  File "/Users/Laurenglading/.local/share/virtualenvs/django-Gmn16L8d/lib/python3.6/site-packages/django/utils/functional.py", line 36, in __get__
    res = instance.__dict__[self.name] = self.func(instance)
  File "/Users/Laurenglading/.local/share/virtualenvs/django-Gmn16L8d/lib/python3.6/site-packages/django/urls/resolvers.py", line 529, in urlconf_module
    return import_module(self.urlconf_name)
  File "/Users/Laurenglading/.local/share/virtualenvs/django-Gmn16L8d/lib/python3.6/importlib/__init__.py", line 126, in import_module
    return _bootstrap._gcd_import(name[level:], package, level)
  File "<frozen importlib._bootstrap>", line 994, in _gcd_import
  File "<frozen importlib._bootstrap>", line 971, in _find_and_load
  File "<frozen importlib._bootstrap>", line 955, in _find_and_load_unlocked
  File "<frozen importlib._bootstrap>", line 665, in _load_unlocked
  File "<frozen importlib._bootstrap_external>", line 678, in exec_module
  File "<frozen importlib._bootstrap>", line 219, in _call_with_frames_removed
  File "/Users/Laurenglading/Desktop/PYTHON/django/mysite/urls.py", line 21, in <module>
    path('', include('pages.urls')),
  File "/Users/Laurenglading/.local/share/virtualenvs/django-Gmn16L8d/lib/python3.6/site-packages/django/urls/conf.py", line 34, in include
    urlconf_module = import_module(urlconf_module)
  File "/Users/Laurenglading/.local/share/virtualenvs/django-Gmn16L8d/lib/python3.6/importlib/__init__.py", line 126, in import_module
    return _bootstrap._gcd_import(name[level:], package, level)
  File "<frozen importlib._bootstrap>", line 994, in _gcd_import
  File "<frozen importlib._bootstrap>", line 971, in _find_and_load
  File "<frozen importlib._bootstrap>", line 955, in _find_and_load_unlocked
  File "<frozen importlib._bootstrap>", line 665, in _load_unlocked
  File "<frozen importlib._bootstrap_external>", line 678, in exec_module
  File "<frozen importlib._bootstrap>", line 219, in _call_with_frames_removed
  File "/Users/Laurenglading/Desktop/PYTHON/django/pages/urls.py", line 4, in <module>
    path('', views.homepageview, name = 'home')
AttributeError: module 'pages.views' has no attribute 'homepageview'
Performing system checks...

Unhandled exception in thread started by <function check_errors.<locals>.wrapper at 0x108298730>
Traceback (most recent call last):
  File "/Users/Laurenglading/.local/share/virtualenvs/django-Gmn16L8d/lib/python3.6/site-packages/django/utils/autoreload.py", line 225, in wrapper
    fn(*args, **kwargs)
  File "/Users/Laurenglading/.local/share/virtualenvs/django-Gmn16L8d/lib/python3.6/site-packages/django/core/management/commands/runserver.py", line 121, in inner_run
    self.check(display_num_errors=True)
  File "/Users/Laurenglading/.local/share/virtualenvs/django-Gmn16L8d/lib/python3.6/site-packages/django/core/management/base.py", line 364, in check
    include_deployment_checks=include_deployment_checks,
  File "/Users/Laurenglading/.local/share/virtualenvs/django-Gmn16L8d/lib/python3.6/site-packages/django/core/management/base.py", line 351, in _run_checks
    return checks.run_checks(**kwargs)
  File "/Users/Laurenglading/.local/share/virtualenvs/django-Gmn16L8d/lib/python3.6/site-packages/django/core/checks/registry.py", line 73, in run_checks
    new_errors = check(app_configs=app_configs)
  File "/Users/Laurenglading/.local/share/virtualenvs/django-Gmn16L8d/lib/python3.6/site-packages/django/core/checks/urls.py", line 13, in check_url_config
    return check_resolver(resolver)
  File "/Users/Laurenglading/.local/share/virtualenvs/django-Gmn16L8d/lib/python3.6/site-packages/django/core/checks/urls.py", line 23, in check_resolver
    return check_method()
  File "/Users/Laurenglading/.local/share/virtualenvs/django-Gmn16L8d/lib/python3.6/site-packages/django/urls/resolvers.py", line 397, in check
    for pattern in self.url_patterns:
  File "/Users/Laurenglading/.local/share/virtualenvs/django-Gmn16L8d/lib/python3.6/site-packages/django/utils/functional.py", line 36, in __get__
    res = instance.__dict__[self.name] = self.func(instance)
  File "/Users/Laurenglading/.local/share/virtualenvs/django-Gmn16L8d/lib/python3.6/site-packages/django/urls/resolvers.py", line 536, in url_patterns
    patterns = getattr(self.urlconf_module, "urlpatterns", self.urlconf_module)
  File "/Users/Laurenglading/.local/share/virtualenvs/django-Gmn16L8d/lib/python3.6/site-packages/django/utils/functional.py", line 36, in __get__
    res = instance.__dict__[self.name] = self.func(instance)
  File "/Users/Laurenglading/.local/share/virtualenvs/django-Gmn16L8d/lib/python3.6/site-packages/django/urls/resolvers.py", line 529, in urlconf_module
    return import_module(self.urlconf_name)
  File "/Users/Laurenglading/.local/share/virtualenvs/django-Gmn16L8d/lib/python3.6/importlib/__init__.py", line 126, in import_module
    return _bootstrap._gcd_import(name[level:], package, level)
  File "<frozen importlib._bootstrap>", line 994, in _gcd_import
  File "<frozen importlib._bootstrap>", line 971, in _find_and_load
  File "<frozen importlib._bootstrap>", line 955, in _find_and_load_unlocked
  File "<frozen importlib._bootstrap>", line 665, in _load_unlocked
  File "<frozen importlib._bootstrap_external>", line 678, in exec_module
  File "<frozen importlib._bootstrap>", line 219, in _call_with_frames_removed
  File "/Users/Laurenglading/Desktop/PYTHON/django/mysite/urls.py", line 21, in <module>
    path('', include('pages.urls')),
  File "/Users/Laurenglading/.local/share/virtualenvs/django-Gmn16L8d/lib/python3.6/site-packages/django/urls/conf.py", line 34, in include
    urlconf_module = import_module(urlconf_module)
  File "/Users/Laurenglading/.local/share/virtualenvs/django-Gmn16L8d/lib/python3.6/importlib/__init__.py", line 126, in import_module
    return _bootstrap._gcd_import(name[level:], package, level)
  File "<frozen importlib._bootstrap>", line 994, in _gcd_import
  File "<frozen importlib._bootstrap>", line 971, in _find_and_load
  File "<frozen importlib._bootstrap>", line 955, in _find_and_load_unlocked
  File "<frozen importlib._bootstrap>", line 665, in _load_unlocked
  File "<frozen importlib._bootstrap_external>", line 678, in exec_module
  File "<frozen importlib._bootstrap>", line 219, in _call_with_frames_removed
  File "/Users/Laurenglading/Desktop/PYTHON/django/pages/urls.py", line 2, in <module>
    from . import views
  File "/Users/Laurenglading/Desktop/PYTHON/django/pages/views.py", line 2, in <module>
    from django.http import HttpResponses
ImportError: cannot import name 'HttpResponses'
Performing system checks...

Unhandled exception in thread started by <function check_errors.<locals>.wrapper at 0x110287950>
Traceback (most recent call last):
  File "/Users/Laurenglading/.local/share/virtualenvs/django-Gmn16L8d/lib/python3.6/site-packages/django/utils/autoreload.py", line 225, in wrapper
    fn(*args, **kwargs)
  File "/Users/Laurenglading/.local/share/virtualenvs/django-Gmn16L8d/lib/python3.6/site-packages/django/core/management/commands/runserver.py", line 121, in inner_run
    self.check(display_num_errors=True)
  File "/Users/Laurenglading/.local/share/virtualenvs/django-Gmn16L8d/lib/python3.6/site-packages/django/core/management/base.py", line 364, in check
    include_deployment_checks=include_deployment_checks,
  File "/Users/Laurenglading/.local/share/virtualenvs/django-Gmn16L8d/lib/python3.6/site-packages/django/core/management/base.py", line 351, in _run_checks
    return checks.run_checks(**kwargs)
  File "/Users/Laurenglading/.local/share/virtualenvs/django-Gmn16L8d/lib/python3.6/site-packages/django/core/checks/registry.py", line 73, in run_checks
    new_errors = check(app_configs=app_configs)
  File "/Users/Laurenglading/.local/share/virtualenvs/django-Gmn16L8d/lib/python3.6/site-packages/django/core/checks/urls.py", line 13, in check_url_config
    return check_resolver(resolver)
  File "/Users/Laurenglading/.local/share/virtualenvs/django-Gmn16L8d/lib/python3.6/site-packages/django/core/checks/urls.py", line 23, in check_resolver
    return check_method()
  File "/Users/Laurenglading/.local/share/virtualenvs/django-Gmn16L8d/lib/python3.6/site-packages/django/urls/resolvers.py", line 397, in check
    for pattern in self.url_patterns:
  File "/Users/Laurenglading/.local/share/virtualenvs/django-Gmn16L8d/lib/python3.6/site-packages/django/utils/functional.py", line 36, in __get__
    res = instance.__dict__[self.name] = self.func(instance)
  File "/Users/Laurenglading/.local/share/virtualenvs/django-Gmn16L8d/lib/python3.6/site-packages/django/urls/resolvers.py", line 536, in url_patterns
    patterns = getattr(self.urlconf_module, "urlpatterns", self.urlconf_module)
  File "/Users/Laurenglading/.local/share/virtualenvs/django-Gmn16L8d/lib/python3.6/site-packages/django/utils/functional.py", line 36, in __get__
    res = instance.__dict__[self.name] = self.func(instance)
  File "/Users/Laurenglading/.local/share/virtualenvs/django-Gmn16L8d/lib/python3.6/site-packages/django/urls/resolvers.py", line 529, in urlconf_module
    return import_module(self.urlconf_name)
  File "/Users/Laurenglading/.local/share/virtualenvs/django-Gmn16L8d/lib/python3.6/importlib/__init__.py", line 126, in import_module
    return _bootstrap._gcd_import(name[level:], package, level)
  File "<frozen importlib._bootstrap>", line 994, in _gcd_import
  File "<frozen importlib._bootstrap>", line 971, in _find_and_load
  File "<frozen importlib._bootstrap>", line 955, in _find_and_load_unlocked
  File "<frozen importlib._bootstrap>", line 665, in _load_unlocked
  File "<frozen importlib._bootstrap_external>", line 678, in exec_module
  File "<frozen importlib._bootstrap>", line 219, in _call_with_frames_removed
  File "/Users/Laurenglading/Desktop/PYTHON/django/mysite/urls.py", line 21, in <module>
    path('', include('pages.urls')),
  File "/Users/Laurenglading/.local/share/virtualenvs/django-Gmn16L8d/lib/python3.6/site-packages/django/urls/conf.py", line 34, in include
    urlconf_module = import_module(urlconf_module)
  File "/Users/Laurenglading/.local/share/virtualenvs/django-Gmn16L8d/lib/python3.6/importlib/__init__.py", line 126, in import_module
    return _bootstrap._gcd_import(name[level:], package, level)
  File "<frozen importlib._bootstrap>", line 994, in _gcd_import
  File "<frozen importlib._bootstrap>", line 971, in _find_and_load
  File "<frozen importlib._bootstrap>", line 955, in _find_and_load_unlocked
  File "<frozen importlib._bootstrap>", line 665, in _load_unlocked
  File "<frozen importlib._bootstrap_external>", line 678, in exec_module
  File "<frozen importlib._bootstrap>", line 219, in _call_with_frames_removed
  File "/Users/Laurenglading/Desktop/PYTHON/django/pages/urls.py", line 2, in <module>
    from . import views
  File "/Users/Laurenglading/Desktop/PYTHON/django/pages/views.py", line 2, in <module>
    from django.http import HttpResponses
ImportError: cannot import name 'HttpResponses'
python manage.py runserver
ls
^C(django-Gmn16L8d) bash-3.2$ python manage.py runserver
Performing system checks...

Unhandled exception in thread started by <function check_errors.<locals>.wrapper at 0x10d7dc950>
Traceback (most recent call last):
  File "/Users/Laurenglading/.local/share/virtualenvs/django-Gmn16L8d/lib/python3.6/site-packages/django/utils/autoreload.py", line 225, in wrapper
    fn(*args, **kwargs)
  File "/Users/Laurenglading/.local/share/virtualenvs/django-Gmn16L8d/lib/python3.6/site-packages/django/core/management/commands/runserver.py", line 121, in inner_run
    self.check(display_num_errors=True)
  File "/Users/Laurenglading/.local/share/virtualenvs/django-Gmn16L8d/lib/python3.6/site-packages/django/core/management/base.py", line 364, in check
    include_deployment_checks=include_deployment_checks,
  File "/Users/Laurenglading/.local/share/virtualenvs/django-Gmn16L8d/lib/python3.6/site-packages/django/core/management/base.py", line 351, in _run_checks
    return checks.run_checks(**kwargs)
  File "/Users/Laurenglading/.local/share/virtualenvs/django-Gmn16L8d/lib/python3.6/site-packages/django/core/checks/registry.py", line 73, in run_checks
    new_errors = check(app_configs=app_configs)
  File "/Users/Laurenglading/.local/share/virtualenvs/django-Gmn16L8d/lib/python3.6/site-packages/django/core/checks/urls.py", line 13, in check_url_config
    return check_resolver(resolver)
  File "/Users/Laurenglading/.local/share/virtualenvs/django-Gmn16L8d/lib/python3.6/site-packages/django/core/checks/urls.py", line 23, in check_resolver
    return check_method()
  File "/Users/Laurenglading/.local/share/virtualenvs/django-Gmn16L8d/lib/python3.6/site-packages/django/urls/resolvers.py", line 397, in check
    for pattern in self.url_patterns:
  File "/Users/Laurenglading/.local/share/virtualenvs/django-Gmn16L8d/lib/python3.6/site-packages/django/utils/functional.py", line 36, in __get__
    res = instance.__dict__[self.name] = self.func(instance)
  File "/Users/Laurenglading/.local/share/virtualenvs/django-Gmn16L8d/lib/python3.6/site-packages/django/urls/resolvers.py", line 536, in url_patterns
    patterns = getattr(self.urlconf_module, "urlpatterns", self.urlconf_module)
  File "/Users/Laurenglading/.local/share/virtualenvs/django-Gmn16L8d/lib/python3.6/site-packages/django/utils/functional.py", line 36, in __get__
    res = instance.__dict__[self.name] = self.func(instance)
  File "/Users/Laurenglading/.local/share/virtualenvs/django-Gmn16L8d/lib/python3.6/site-packages/django/urls/resolvers.py", line 529, in urlconf_module
    return import_module(self.urlconf_name)
  File "/Users/Laurenglading/.local/share/virtualenvs/django-Gmn16L8d/lib/python3.6/importlib/__init__.py", line 126, in import_module
    return _bootstrap._gcd_import(name[level:], package, level)
  File "<frozen importlib._bootstrap>", line 994, in _gcd_import
  File "<frozen importlib._bootstrap>", line 971, in _find_and_load
  File "<frozen importlib._bootstrap>", line 955, in _find_and_load_unlocked
  File "<frozen importlib._bootstrap>", line 665, in _load_unlocked
  File "<frozen importlib._bootstrap_external>", line 678, in exec_module
  File "<frozen importlib._bootstrap>", line 219, in _call_with_frames_removed
  File "/Users/Laurenglading/Desktop/PYTHON/django/mysite/urls.py", line 21, in <module>
    path('', include('pages.urls')),
  File "/Users/Laurenglading/.local/share/virtualenvs/django-Gmn16L8d/lib/python3.6/site-packages/django/urls/conf.py", line 34, in include
    urlconf_module = import_module(urlconf_module)
  File "/Users/Laurenglading/.local/share/virtualenvs/django-Gmn16L8d/lib/python3.6/importlib/__init__.py", line 126, in import_module
    return _bootstrap._gcd_import(name[level:], package, level)
  File "<frozen importlib._bootstrap>", line 994, in _gcd_import
  File "<frozen importlib._bootstrap>", line 971, in _find_and_load
  File "<frozen importlib._bootstrap>", line 955, in _find_and_load_unlocked
  File "<frozen importlib._bootstrap>", line 665, in _load_unlocked
  File "<frozen importlib._bootstrap_external>", line 678, in exec_module
  File "<frozen importlib._bootstrap>", line 219, in _call_with_frames_removed
  File "/Users/Laurenglading/Desktop/PYTHON/django/pages/urls.py", line 2, in <module>
    from . import views
  File "/Users/Laurenglading/Desktop/PYTHON/django/pages/views.py", line 2, in <module>
    from django.http import HttpResponses
ImportError: cannot import name 'HttpResponses'
^C(django-Gmn16L8d) bash-3.2$ cd desktop
bash: cd: desktop: No such file or directory
(django-Gmn16L8d) bash-3.2$ pages
bash: pages: command not found
(django-Gmn16L8d) bash-3.2$ python manage.py runserver
Performing system checks...

Unhandled exception in thread started by <function check_errors.<locals>.wrapper at 0x104822950>
Traceback (most recent call last):
  File "/Users/Laurenglading/.local/share/virtualenvs/django-Gmn16L8d/lib/python3.6/site-packages/django/utils/autoreload.py", line 225, in wrapper
    fn(*args, **kwargs)
  File "/Users/Laurenglading/.local/share/virtualenvs/django-Gmn16L8d/lib/python3.6/site-packages/django/core/management/commands/runserver.py", line 121, in inner_run
    self.check(display_num_errors=True)
  File "/Users/Laurenglading/.local/share/virtualenvs/django-Gmn16L8d/lib/python3.6/site-packages/django/core/management/base.py", line 364, in check
    include_deployment_checks=include_deployment_checks,
  File "/Users/Laurenglading/.local/share/virtualenvs/django-Gmn16L8d/lib/python3.6/site-packages/django/core/management/base.py", line 351, in _run_checks
    return checks.run_checks(**kwargs)
  File "/Users/Laurenglading/.local/share/virtualenvs/django-Gmn16L8d/lib/python3.6/site-packages/django/core/checks/registry.py", line 73, in run_checks
    new_errors = check(app_configs=app_configs)
  File "/Users/Laurenglading/.local/share/virtualenvs/django-Gmn16L8d/lib/python3.6/site-packages/django/core/checks/urls.py", line 13, in check_url_config
    return check_resolver(resolver)
  File "/Users/Laurenglading/.local/share/virtualenvs/django-Gmn16L8d/lib/python3.6/site-packages/django/core/checks/urls.py", line 23, in check_resolver
    return check_method()
  File "/Users/Laurenglading/.local/share/virtualenvs/django-Gmn16L8d/lib/python3.6/site-packages/django/urls/resolvers.py", line 397, in check
    for pattern in self.url_patterns:
  File "/Users/Laurenglading/.local/share/virtualenvs/django-Gmn16L8d/lib/python3.6/site-packages/django/utils/functional.py", line 36, in __get__
    res = instance.__dict__[self.name] = self.func(instance)
  File "/Users/Laurenglading/.local/share/virtualenvs/django-Gmn16L8d/lib/python3.6/site-packages/django/urls/resolvers.py", line 536, in url_patterns
    patterns = getattr(self.urlconf_module, "urlpatterns", self.urlconf_module)
  File "/Users/Laurenglading/.local/share/virtualenvs/django-Gmn16L8d/lib/python3.6/site-packages/django/utils/functional.py", line 36, in __get__
    res = instance.__dict__[self.name] = self.func(instance)
  File "/Users/Laurenglading/.local/share/virtualenvs/django-Gmn16L8d/lib/python3.6/site-packages/django/urls/resolvers.py", line 529, in urlconf_module
    return import_module(self.urlconf_name)
  File "/Users/Laurenglading/.local/share/virtualenvs/django-Gmn16L8d/lib/python3.6/importlib/__init__.py", line 126, in import_module
    return _bootstrap._gcd_import(name[level:], package, level)
  File "<frozen importlib._bootstrap>", line 994, in _gcd_import
  File "<frozen importlib._bootstrap>", line 971, in _find_and_load
  File "<frozen importlib._bootstrap>", line 955, in _find_and_load_unlocked
  File "<frozen importlib._bootstrap>", line 665, in _load_unlocked
  File "<frozen importlib._bootstrap_external>", line 678, in exec_module
  File "<frozen importlib._bootstrap>", line 219, in _call_with_frames_removed
  File "/Users/Laurenglading/Desktop/PYTHON/django/mysite/urls.py", line 21, in <module>
    path('', include('pages.urls')),
  File "/Users/Laurenglading/.local/share/virtualenvs/django-Gmn16L8d/lib/python3.6/site-packages/django/urls/conf.py", line 34, in include
    urlconf_module = import_module(urlconf_module)
  File "/Users/Laurenglading/.local/share/virtualenvs/django-Gmn16L8d/lib/python3.6/importlib/__init__.py", line 126, in import_module
    return _bootstrap._gcd_import(name[level:], package, level)
  File "<frozen importlib._bootstrap>", line 994, in _gcd_import
  File "<frozen importlib._bootstrap>", line 971, in _find_and_load
  File "<frozen importlib._bootstrap>", line 955, in _find_and_load_unlocked
  File "<frozen importlib._bootstrap>", line 665, in _load_unlocked
  File "<frozen importlib._bootstrap_external>", line 678, in exec_module
  File "<frozen importlib._bootstrap>", line 219, in _call_with_frames_removed
  File "/Users/Laurenglading/Desktop/PYTHON/django/pages/urls.py", line 2, in <module>
    from . import views
  File "/Users/Laurenglading/Desktop/PYTHON/django/pages/views.py", line 6
    return HttpResponse(\"<h3> hi lg</h3>")
                                          ^
SyntaxError: unexpected character after line continuation character
python manage.py runserverPerforming system checks...

Unhandled exception in thread started by <function check_errors.<locals>.wrapper at 0x102f10950>
Traceback (most recent call last):
  File "/Users/Laurenglading/.local/share/virtualenvs/django-Gmn16L8d/lib/python3.6/site-packages/django/utils/autoreload.py", line 225, in wrapper
    fn(*args, **kwargs)
  File "/Users/Laurenglading/.local/share/virtualenvs/django-Gmn16L8d/lib/python3.6/site-packages/django/core/management/commands/runserver.py", line 121, in inner_run
    self.check(display_num_errors=True)
  File "/Users/Laurenglading/.local/share/virtualenvs/django-Gmn16L8d/lib/python3.6/site-packages/django/core/management/base.py", line 364, in check
    include_deployment_checks=include_deployment_checks,
  File "/Users/Laurenglading/.local/share/virtualenvs/django-Gmn16L8d/lib/python3.6/site-packages/django/core/management/base.py", line 351, in _run_checks
    return checks.run_checks(**kwargs)
  File "/Users/Laurenglading/.local/share/virtualenvs/django-Gmn16L8d/lib/python3.6/site-packages/django/core/checks/registry.py", line 73, in run_checks
    new_errors = check(app_configs=app_configs)
  File "/Users/Laurenglading/.local/share/virtualenvs/django-Gmn16L8d/lib/python3.6/site-packages/django/core/checks/urls.py", line 13, in check_url_config
    return check_resolver(resolver)
  File "/Users/Laurenglading/.local/share/virtualenvs/django-Gmn16L8d/lib/python3.6/site-packages/django/core/checks/urls.py", line 23, in check_resolver
    return check_method()
  File "/Users/Laurenglading/.local/share/virtualenvs/django-Gmn16L8d/lib/python3.6/site-packages/django/urls/resolvers.py", line 397, in check
    for pattern in self.url_patterns:
  File "/Users/Laurenglading/.local/share/virtualenvs/django-Gmn16L8d/lib/python3.6/site-packages/django/utils/functional.py", line 36, in __get__
    res = instance.__dict__[self.name] = self.func(instance)
  File "/Users/Laurenglading/.local/share/virtualenvs/django-Gmn16L8d/lib/python3.6/site-packages/django/urls/resolvers.py", line 536, in url_patterns
    patterns = getattr(self.urlconf_module, "urlpatterns", self.urlconf_module)
  File "/Users/Laurenglading/.local/share/virtualenvs/django-Gmn16L8d/lib/python3.6/site-packages/django/utils/functional.py", line 36, in __get__
    res = instance.__dict__[self.name] = self.func(instance)
  File "/Users/Laurenglading/.local/share/virtualenvs/django-Gmn16L8d/lib/python3.6/site-packages/django/urls/resolvers.py", line 529, in urlconf_module
    return import_module(self.urlconf_name)
  File "/Users/Laurenglading/.local/share/virtualenvs/django-Gmn16L8d/lib/python3.6/importlib/__init__.py", line 126, in import_module
    return _bootstrap._gcd_import(name[level:], package, level)
  File "<frozen importlib._bootstrap>", line 994, in _gcd_import
  File "<frozen importlib._bootstrap>", line 971, in _find_and_load
  File "<frozen importlib._bootstrap>", line 955, in _find_and_load_unlocked
  File "<frozen importlib._bootstrap>", line 665, in _load_unlocked
  File "<frozen importlib._bootstrap_external>", line 678, in exec_module
  File "<frozen importlib._bootstrap>", line 219, in _call_with_frames_removed
  File "/Users/Laurenglading/Desktop/PYTHON/django/mysite/urls.py", line 21, in <module>
    path('', include('pages.urls')),
  File "/Users/Laurenglading/.local/share/virtualenvs/django-Gmn16L8d/lib/python3.6/site-packages/django/urls/conf.py", line 34, in include
    urlconf_module = import_module(urlconf_module)
  File "/Users/Laurenglading/.local/share/virtualenvs/django-Gmn16L8d/lib/python3.6/importlib/__init__.py", line 126, in import_module
    return _bootstrap._gcd_import(name[level:], package, level)
  File "<frozen importlib._bootstrap>", line 994, in _gcd_import
  File "<frozen importlib._bootstrap>", line 971, in _find_and_load
  File "<frozen importlib._bootstrap>", line 955, in _find_and_load_unlocked
  File "<frozen importlib._bootstrap>", line 665, in _load_unlocked
  File "<frozen importlib._bootstrap_external>", line 678, in exec_module
  File "<frozen importlib._bootstrap>", line 219, in _call_with_frames_removed
  File "/Users/Laurenglading/Desktop/PYTHON/django/pages/urls.py", line 2, in <module>
    from . import views
  File "/Users/Laurenglading/Desktop/PYTHON/django/pages/views.py", line 2, in <module>
    from django.http import HttpResponses
ImportError: cannot import name 'HttpResponses'
Performing system checks...

python manage.py runserverSystem check identified no issues (0 silenced).

You have 14 unapplied migration(s). Your project may not work properly until you apply the migrations for app(s): admin, auth, contenttypes, sessions.
Run 'python manage.py migrate' to apply them.

February 16, 2018 - 22:55:01
Django version 2.0.2, using settings 'mysite.settings'
Starting development server at http://127.0.0.1:8000/
Quit the server with CONTROL-C.
[16/Feb/2018 22:55:18] "GET /static/admin/fonts/Roboto-Bold-webfont.woff HTTP/1.1" 304 0
[16/Feb/2018 22:55:18] "GET /static/admin/fonts/Roboto-Light-webfont.woff HTTP/1.1" 304 0
[16/Feb/2018 22:55:18] "GET /static/admin/fonts/Roboto-Regular-webfont.woff HTTP/1.1" 304 0
[16/Feb/2018 22:55:18] "GET /static/admin/css/fonts.css HTTP/1.1" 304 0
[16/Feb/2018 22:55:18] "GET / HTTP/1.1" 200 15
[16/Feb/2018 22:55:27] "GET / HTTP/1.1" 200 15

